<?xml version="1.0"?>
<robot name="car" xmlns:xacro="http://ros.org/wiki/xacro">

	<xacro:property name="base_length" value="0.47"/>
	<xacro:property name="base_width" value="1.05"/>
	<xacro:property name="base_height" value="0.3"/>
	<xacro:property name="wheel_radius" value="0.10"/>
	<xacro:property name="wheel_width" value="0.085"/>


	<link name="base_link">
		<visual>
			<geometry>
				<box size="${base_length} ${base_width} ${base_height}" />
			</geometry>
			<material name="black">
				<color rgba="0.0 0.0 0.0 1.0" />
			</material>
		</visual>
	</link>

	<link name="R_rear_link">
		<visual>
			<origin xyz="0 0 0" rpy="${pi/2} 0 0" />
			<geometry>
				<cylinder radius="${wheel_radius}" length="${wheel_width}" />
			</geometry>
			<material name="red">
				<color rgba="1.0 0.0 0.0 1.0" />
			</material>
		</visual>
	</link>

	<joint name="R_rear_joint" type="continuous">
		<parent link="base_link" />
		<child link="R_rear_link" />
		<origin xyz="0.2175 -0.355 -0.11" rpy="0 0 ${pi/2}" />
		<axis xyz="0 1 0" />
	</joint>

        <link name="L_rear_link">
                <visual>
                        <origin xyz="0 0 0" rpy="${pi/2} 0 0" />
                        <geometry>
                                <cylinder radius="${wheel_radius}" length="${wheel_width}" />
                        </geometry>
                        <material name="red">
                                <color rgba="1.0 0.0 0.0 1.0" />
                        </material>
                </visual>
        </link>

        <joint name="L_rear_joint" type="continuous">
                <parent link="base_link" />
                <child link="L_rear_link" />
                <origin xyz="-0.2175 -0.355 -0.11" rpy="0 0 ${pi/2}" />
                <axis xyz="0 1 0" />
        </joint>
	
	 <link name="R_front_pivot_link">
                <visual>
			<origin xyz="0 0 0" rpy="0 0 0" />
                        <geometry>
                                <cylinder radius="0.025" length="0.035" />
                        </geometry>
                        <material name="blue">
                                <color rgba="0.0 0.0 1.0 1.0" />
                        </material>
                </visual>
        </link>

        <link name="R_front_link">
                <visual>
                        <origin xyz="0 0 0" rpy="${pi/2} 0 0" />
                        <geometry>
                                <cylinder radius="${wheel_radius}" length="${wheel_width}" />
                        </geometry>
                        <material name="red">
                                <color rgba="1.0 0.0 0.0 1.0" />
                        </material>
                </visual>
        </link>

        <joint name="R_base_pivot_joint" type="continuous">
                <parent link="base_link" />
                <child link="R_front_pivot_link" />
                <origin xyz="0.145 0.21 -0.11" rpy="0 0 ${pi/2}" />
                <axis xyz="0 0 1" />
        </joint>

        <joint name="R_pivot_wheel_joint" type="continuous">
                <parent link="R_front_pivot_link" />
                <child link="R_front_link" />
                <origin xyz="0.0725 0 0" rpy="0 0 ${pi/2}" />
                <axis xyz="0 1 0" />
        </joint>


	<link name="L_front_pivot_link">
                <visual>
			<origin xyz="0 0 0" rpy="0 0 0" />
                        <geometry>
                                <cylinder radius="0.025" length="0.035" />
                        </geometry>
                        <material name="blue">
                                <color rgba="0.0 0.0 1.0 1.0" />
                        </material>
                </visual>
        </link>

        <link name="L_front_link">
                <visual>
                        <origin xyz="0 0 0" rpy="${pi/2} 0 0" />
                        <geometry>
                                <cylinder radius="${wheel_radius}" length="${wheel_width}" />
                        </geometry>
                        <material name="red">
                                <color rgba="1.0 0.0 0.0 1.0" />
                        </material>
                </visual>
        </link>

        <joint name="L_base_pivot_joint" type="continuous">
                <parent link="base_link" />
                <child link="L_front_pivot_link" />
                <origin xyz="-0.145 0.21 -0.11" rpy="0 0 ${pi/2}" />
                <axis xyz="0 0 1" />
        </joint>

        <joint name="L_pivot_wheel_joint" type="continuous">
                <parent link="L_front_pivot_link" />
                <child link="L_front_link" />
                <origin xyz="-0.0725 0 0" rpy="0 0 ${pi/2}" />
                <axis xyz="0 1 0" />
        </joint>

        <link name="front_baton">
                <visual>
			<origin xyz="0 0 0" rpy="${pi/2} 0 0" />
                        <geometry>
                                <cylinder radius="0.01" length="0.29" />
                        </geometry>
                        <material name="green">
                                <color rgba="0.0 1.0 0.0 1.0" />
                        </material>
                </visual>
        </link>


        <joint name="baton_joint" type="fixed">
                <parent link="base_link"/>
                <child link="front_baton"/>
                <origin xyz="0 0.28 -0.11" rpy="0 0 ${pi/2}" />
                <axis xyz="0 0 1" />
        </joint>

	
        <joint name="L_baton_joint" type="revolute">
                <parent link="front_baton"/>
                <child link="L_front_pivot_link"/>
                <origin xyz="0.0 -0.145 0.0" rpy="0 0 ${pi/2}" />
                <axis xyz="0 0 1" />
		<limit lower="${-pi/9}" upper="${pi/9}" effort="0.5293" velocity="0.1745" />
        </joint>
	
	
        <joint name="R_baton_joint" type="revolute">
                <parent link="front_baton"/>
                <child link="R_front_pivot_link"/>
                <origin xyz="0 0.145 0.0" rpy="0 0 ${pi/2}" />
                <axis xyz="0 0 1" />
                <limit lower="${-pi/9}" upper="${pi/9}" effort="0.5293" velocity="0.1745" />		
		<mimic joint="L_baton_joint" multiplier="1" offset="0"/>
        </joint>
	

        <link name="chassis_lidar">
                <visual>
			<origin xyz="0 0 0" rpy="0 0 0" />
                        <geometry>
                                <box size="0.008 0.118 0.1"/>
                        </geometry>
                        <material name="random">
                                <color rgba="1.0 1.0 0.0 1.0"/>
                        </material>
                </visual>
        </link>


        <joint name="chassis_lidar_joint" type="fixed">
		<parent link="base_link" />
		<child link="chassis_lidar" />
		<origin xyz="0.0 -0.35 0.20" rpy="0 0 ${pi/2}"/>
	</joint>


        <link name="base_lidar">
                <visual>
			<origin xyz="0 0 0" rpy="0 0 0" />
                        <geometry>
                                <box size="0.08 0.118 0.008"/>
                        </geometry>
                        <material name="random">
                                <color rgba="1.0 1.0 0.0 1.0"/>
                        </material>
                </visual>
        </link>


        <joint name="base_lidar_joint" type="fixed">
                <parent link="chassis_lidar" />
                <child link="base_lidar" />
                <origin xyz="-0.04 0 0.05" rpy="0 0 0"/>
        </joint>



	<link name="laser">
		<visual>
			<origin xyz="0 0 0" rpy="0 0 0" />
			<geometry>
				<cylinder radius="0.035" length="0.041"/>
			</geometry>
			<material name="lidar">
				<color rgba="1.0 0.0 1.0 1.0"/>
			</material>
		</visual>
	</link>	

	<link name="base_footprint">
		<visual>
			<geometry>
				<cylinder radius="0.035" length="0.041"/>
			</geometry>
			<material name="odom">
				<color rgba="1.0 0.0 1.0 1.0"/>
			</material>
		</visual>
	</link>	
	
  <joint name="lidar_joint" type="fixed">
    <parent link="base_lidar"/>
    <child link="laser"/>
    <origin xyz="0 0 0.0205" rpy="0 0 ${pi/2}"/>
  </joint>
  <joint name="base_footprint_joint" type="fixed">
    <parent link="base_link"/>
    <child link="base_footprint"/>
    <origin xyz="0 0 0" rpy="0 0 0"/>
  </joint>


<gazebo reference="laser">
    <sensor name="lidar" type="ray">
      <always_on>true</always_on>
      <visualize>true</visualize>
      <update_rate>5</update_rate>
      <ray>
        <scan>
          <horizontal>
            <samples>360</samples>
            <resolution>1.000000</resolution>
            <min_angle>0.000000</min_angle>
            <max_angle>6.280000</max_angle>
          </horizontal>
        </scan>
        <range>
          <min>0.120000</min>
          <max>3.5</max>
          <resolution>0.015000</resolution>
        </range>
        <noise>
          <type>gaussian</type>
          <mean>0.0</mean>
          <stddev>0.01</stddev>
        </noise>
      </ray>
      <plugin name="scan" filename="libgazebo_ros_ray_sensor.so">
        <ros>
          <remapping>~/out:=scan</remapping>
        </ros>
        <output_type>sensor_msgs/LaserScan</output_type>
        <frame_name>laser</frame_name>
      </plugin>
    </sensor>
  </gazebo>
</robot>
