<?xml version="1.0"?>
<robot name="car" xmlns:xacro="http://ros.org/wiki/xacro">

	<xacro:property name="base_width" value="0.5"/>
	<xacro:property name="base_length" value="1.05"/>
	<xacro:property name="base_height" value="0.43"/>
	<xacro:property name="wheel_radius" value="0.10"/>
	<xacro:property name="wheel_width" value="0.085"/>


	<!-- Carcasse de la voiture -->
	<link name="base_link">
		<visual>
			<geometry>
				<box size="${base_length} ${base_width} ${base_height}" />
			</geometry>
			<material name="black">
				<color rgba="0.0 0.0 0.0 1.0" />
			</material>
		</visual>
	</link>

	<!-- Roue arrière droite -->
	<link name="R_rear_link">
		<visual>
			<origin xyz="0 0 0" rpy="${pi/2} 0 0" />
			<geometry>
				<cylinder radius="${wheel_radius}" length="${wheel_width}" />
			</geometry>
			<material name="red">
				<color rgba="1.0 0.0 0.0 1.0" />
			</material>
		</visual>
	</link>

	<joint name="R_rear_joint" type="continuous">
		<parent link="base_link" />
		<child link="R_rear_link" />
		<origin xyz="-0.355 0.2175 -0.175" rpy="0 0 0" />
		<axis xyz="0 1 0" />
	</joint>

	<!-- Roue arrière gauche -->
	<link name="L_rear_link">
		<visual>
			<origin xyz="0 0 0" rpy="${pi/2} 0 0" />
			<geometry>
				<cylinder radius="${wheel_radius}" length="${wheel_width}" />
			</geometry>
			<material name="red">
				<color rgba="1.0 0.0 0.0 1.0" />
			</material>
		</visual>
	</link>

	<joint name="L_rear_joint" type="continuous">
		<parent link="base_link" />
		<child link="L_rear_link" />
		<origin xyz="-0.355 -0.2175 -0.175" rpy="0 0 0" />
		<axis xyz="0 1 0" />
	</joint>

	<!-- Roue avant droite -->

	<link name="R_front_pivot_link">
		<visual>
			<geometry>
				<cylinder radius="0.025" length="0.035" />
			</geometry>
			<material name="blue">
				<color rgba="0.0 1.0 0.0 1.0" />
			</material>
		</visual>
	</link>
	
	<link name="R_front_link">
		<visual>
			<origin xyz="0 0 0" rpy="${pi/2} 0 0" />
			<geometry>
				<cylinder radius="${wheel_radius}" length="${wheel_width}" />
			</geometry>
			<material name="red">
				<color rgba="1.0 0.0 0.0 1.0" />
			</material>
		</visual>
	</link>

	<joint name="R_base_pivot_joint" type="continuous">
		<parent link="base_link" />
		<child link="R_front_pivot_link" />
		<origin xyz="0.21 0.145 0" rpy="0 0 0" />
		<axis xyz="0 0 1" />
	</joint>

	<joint name="R_pivot_wheel_joint" type="continuous">
		<parent link="R_front_pivot_link" />
		<child link="R_front_link" />
		<origin xyz="0 0.725 0" rpy="0 0 0" />
		<axis xyz="0 1 0" />
	</joint>

</robot>
